Workbook

Sheet Raw_data
A1: Order_ID | B1: Order_Date | C1: Customer_ID | D1: Product_ID | E1: Product_Name | F1: Category | G1: Region | H1: City | I1: Quantity | J1: Unit_Price | K1: Discount | L1: Sales_Amount | M1: Sales_Channel | N1: Payment_Method | O1: Order_Status | P1: Salesperson | R1: Total Records | S1: =COUNTA(A2:A1529) -> 1528
A2: ORD50001 | B2: 45373 | C2: CUST1224 | D2: P012 | E2: Water Bottle | F2: Accessories | G2: East | H2: Kolkata | I2: 3 | J2: 876.84 | K2: 0.08 | L2: 2420.08 | M2: Online | N2: Debit Card | O2: Returned | P2: Arjun | R2: Total Colums | S2: 16
A3: ORD50002 | B3: 45986 | C3: CUST1131 | D3: P011 | E3: Headphones | F3: Electronics | G3: West | H3: Pune | I3: 3 | J3: 3174.6 | K3: 0 | L3: 9523.8 | M3: Online | N3: Cash on Delivery | O3: Cancelled | P3: Arjun | R3: Missing Customer ID | S3: =COUNTBLANK(C2:C1529) -> 35
A4: ORD50003 | B4: 45659 | C4: CUST1060 | D4: P013 | E4: Desk Lamp | F4: Furniture | G4: East | H4: Ranchi | I4: 3 | J4: 1613.97 | K4: 0.08 | L4: 4454.56 | M4: Online | N4: Cash on Delivery | O4: Cancelled | P4: Rahul | R4: Missing Cities | S4: =COUNTBLANK(H2:H1529) -> 22
A5: ORD50004 | B5: 45868 | C5: CUST1116 | D5: P003 | E5: Keyboard | F5: Electronics | G5: West | H5: Surat | I5: 4 | J5: 1935.56 | K5: 0.05 | L5: 7355.13 | M5: Marketplace | N5: Net Banking | O5: Cancelled | P5: Priya | R5: Missing Quantities | S5: =COUNTBLANK(I2:I1529) -> 12
A6: ORD50005 | B6: 45623 | C6: CUST1041 | D6: P008 | E6: Pen Set | F6: Stationery | G6: South | H6: Chennai | I6: 1 | J6: 226.44 | K6: 0.08 | L6: 208.32 | M6: Marketplace | N6: Credit Card | O6: Returned | P6: Sneha | R6: Missing Discounts | S6: =COUNTBLANK(K2:K1529) -> 10
A7: ORD50006 | B7: 45589 | C7: CUST1121 | D7: P014 | E7: Webcam | F7: Electronics | G7: South | H7: Hyderabad | I7: 1 | J7: 2660.88 | K7: 0.08 | L7: 2448.01 | M7: Marketplace | N7: Debit Card | O7: Completed | P7: Priya | R7: Missing Payment Method | S7: =COUNTBLANK(N2:N1529) -> 18
A8: ORD50007 | B8: 45806 | C8: CUST1217 | D8: P011 | E8: Headphones | F8: Electronics | G8: West | H8: Mumbai | I8: 3 | J8: 3302.54 | K8: 0.03 | L8: 9610.39 | M8: Online | N8: Net Banking | O8: Cancelled | P8: Sneha | R8: Missing Salesperosns | S8: =COUNTBLANK(P2:P1529) -> 15
A9: ORD50008 | B9: 46025 | C9: CUST1166 | D9: P013 | E9: Desk Lamp | F9: Furniture | G9: South | H9: Hyderabad | I9: 5 | J9: 1646.72 | K9: 0.05 | L9: 7821.92 | M9: Marketplace | N9: UPI | O9: Cancelled | P9: Anil
A10: ORD50009 | B10: 46018 | C10: CUST1184 | D10: P012 | E10: Water Bottle | F10: Accessories | G10: West | H10: Ahmedabad | I10: 4 | J10: 888.18 | K10: 0.08 | L10: 3268.5 | M10: Store | N10: Debit Card | O10: Completed | P10: Anil
A11: ORD50010 | B11: 45419 | C11: CUST1223 | D11: P004 | E11: Monitor 24-inch | F11: Electronics | G11: North | H11: Lucknow | I11: 3 | J11: 12442.19 | K11: 0.1 | L11: 33593.91 | M11: Online | N11: Net Banking | O11: Completed | P11: Arjun
A12: ORD50011 | B12: 45807 | C12: CUST1080 | D12: P009 | E12: Backpack | F12: Accessories | G12: North | H12: Jaipur | I12: 3 | J12: 1664.88 | K12: 0.15 | L12: 4245.44 | M12: Store | N12: Cash on Delivery | O12: Completed | P12: Rahul
A13: ORD50012 | B13: 45664 | C13: CUST1223 | D13: P015 | E13: Phone Stand | F13: Accessories | G13: West | H13: Pune | I13: 1 | J13: 650.53 | K13: 0.03 | L13: 631.01 | M13: Marketplace | N13: Credit Card | O13: Completed | P13: Arjun
A14: ORD50013 | B14: 45407 | C14: CUST1173 | D14: P009 | E14: Backpack | F14: Accessories | G14: East | H14: Bhubaneswar | I14: 4 | J14: 1773.04 | K14: 0.2 | L14: 5673.73 | M14: Marketplace | N14: Credit Card | O14: Completed | P14: Rahul
A15: ORD50014 | B15: 45312 | C15: CUST1187 | D15: P002 | E15: Wireless Mouse | F15: Electronics | G15: North | H15: Delhi | I15: 4 | J15: 1192.68 | K15: 0.15 | L15: 4055.11 | M15: Marketplace | N15: Debit Card | O15: Returned | P15: Priya
A16: ORD50015 | B16: 45745 | C16: CUST1100 | D16: P011 | E16: Headphones | F16: Electronics | G16: South | H16: Bengaluru | I16: 3 | J16: 3098.37 | K16: 0.03 | L16: 9016.26 | M16: Store | N16: Net Banking | O16: Completed | P16: Vikram
A17: ORD50016 | B17: 45371 | C17: CUST1129 | D17: P006 | E17: Desk | F17: Furniture | G17: North | H17: Lucknow | I17: 2 | J17: 7670.68 | K17: 0.2 | L17: 12273.09 | M17: Store | N17: Credit Card | O17: Cancelled | P17: Vikram
A18: ORD50017 | B18: 45532 | C18: CUST1117 | D18: P012 | E18: Water Bottle | F18: Accessories | G18: South | H18: Hyderabad | I18: 4 | J18: 819.02 | K18: 0.15 | L18: 2784.67 | M18: Online | N18: Debit Card | O18: Returned | P18: Priya
A19: ORD50018 | B19: 45707 | C19: CUST1143 | D19: P011 | E19: Headphones | F19: Electronics | G19: North | H19: Delhi | I19: 4 | J19: 3240.56 | K19: 0.05 | L19: 12314.13 | M19: Store | N19: Cash on Delivery | O19: Completed | P19: Meena
A20: ORD50019 | B20: 45741 | C20: CUST1164 | D20: P011 | E20: Headphones | F20: Electronics | G20: East | H20: Kolkata | I20: 3 | J20: 3243.06 | K20: 0.05 | L20: 9242.72 | M20: Store | N20: Net Banking | O20: Completed | P20: Meena
... A31: ORD50030 | B31: 45973 | C31: CUST1009 | D31: P006 | E31: Desk | F31: Furniture | G31: South | H31: Hyderabad | I31: 1 | J31: 6901.6 | K31: 0.2 | L31: 5521.28 | M31: Online | N31: Cash on Delivery | O31: Returned | P31: Priya
A32: ORD50031 | B32: 45973 | D32: P003 | E32: Keyboard | F32: Electronics | G32: South | H32: Visakhapatnam | I32: 3 | J32: 1712.57 | K32: 0.15 | L32: 4367.05 | M32: Online | N32: Cash on Delivery | O32: Cancelled | P32: Rahul
A33: ORD50032 | B33: 46178 | D33: P008 | E33: Pen Set | F33: Stationery | G33: East | H33: Kolkata | I33: 3 | J33: 202.89 | K33: 0.03 | L33: 590.41 | M33: Online | N33: UPI | O33: Completed | P33: Arjun
A34: ORD50033 | B34: 46176 | C34: CUST1181 | D34: P002 | E34: Wireless Mouse | F34: Electronics | G34: South | H34: Visakhapatnam | I34: 0 | J34: 1215.57 | K34: 0.2 | L34: 2917.37 | M34: Online | N34: Cash on Delivery | O34: Cancelled | P34: Anil
A35: ORD50034 | B35: 45944 | C35: CUST1148 | D35: P002 | E35: Wireless Mouse | F35: Electronics | G35: East | H35: Ranchi | I35: 5 | J35: 1127.76 | K35: 0 | L35: 5638.8 | M35: Online | N35: Credit Card | O35: Returned | P35: Rahul
A36: ORD50035 | B36: 45412 | C36: CUST1249 | D36: P008 | E36: Pen Set | F36: Stationery | G36: East | H36: Ranchi | I36: 4 | J36: 212.48 | K36: 0.05 | L36: 807.42 | M36: Marketplace | N36: Debit Card | O36: Completed | P36: Kiran
A37: ORD50036 | B37: 45798 | C37: CUST1195 | D37: P003 | E37: Keyboard | F37: Electronics | G37: East | H37: Bhubaneswar | I37: 5 | J37: 1696.42 | K37: 0 | L37: 8482.1 | M37: Online | N37: Cash on Delivery | O37: Completed | P37: Kiran
A38: ORD50037 | B38: 45457 | C38: CUST1122 | D38: P014 | E38: Webcam | F38: Electronics | G38: East | H38: Ranchi | I38: 5 | J38: 2927.57 | K38: 0.08 | L38: 13466.82 | M38: Online | N38: Net Banking | O38: Completed | P38: Rahul
A39: ORD50038 | B39: 46048 | C39: CUST1199 | D39: P004 | E39: Monitor 24-inch | F39: Electronics | G39: West | H39: Ahmedabad | I39: 3 | J39: 12561.54 | K39: 0.03 | L39: 36554.08 | M39: Marketplace | N39: Cash on Delivery | O39: Cancelled | P39: Kiran
A40: ORD50039 | B40: 45556 | C40: CUST1111 | D40: P007 | E40: Notebook Pack | F40: Stationery | G40: North | H40: Chandigarh | I40: 2 | J40: 460.94 | K40: 0.2 | L40: 737.5 | M40: Marketplace | N40: Credit Card | O40: Completed | P40: Kiran
A41: ORD50040 | B41: 45518 | C41: CUST1250 | D41: P005 | E41: Office Chair | F41: Furniture | G41: North | H41: Delhi | I41: 5 | J41: 9981.18 | K41: 0.15 | L41: 42420.01 | M41: Marketplace | N41: UPI | O41: Completed | P41: Kiran
A42: ORD50041 | B42: 45618 | C42: CUST1081 | D42: P003 | E42: Keyboard | F42: Electronics | G42: North | H42: Chandigarh | I42: 5 | J42: 1697.44 | K42: 0.05 | L42: 8062.84 | M42: Marketplace | N42: Debit Card | O42: Completed | P42: Priya
A43: ORD50042 | B43: 45551 | C43: CUST1185 | D43: P009 | E43: Backpack | F43: Accessories | G43: North | H43: Delhi | I43: 3 | J43: 1662.09 | K43: 0 | L43: 4986.27 | M43: Online | N43: UPI | O43: Cancelled | P43: Anil
A44: ORD50043 | B44: 45683 | C44: CUST1103 | D44: P009 | E44: Backpack | F44: Accessories | G44: East | H44: Ranchi | I44: 4 | J44: 1747.58 | K44: 0.15 | L44: 5941.77 | M44: Store | N44: Net Banking | O44: Returned | P44: Meena
A45: ORD50044 | B45: 46068 | C45: CUST1060 | D45: P009 | E45: Backpack | F45: Accessories | G45: North | H45: Delhi | I45: 3 | J45: 1724.18 | K45: 0.03 | L45: 5017.36 | M45: Store | N45: Debit Card | O45: Returned | P45: Sneha
... A54: ORD50053 | B54: 45821 | C54: CUST1036 | D54: P002 | E54: Wireless Mouse | F54: Electronics | G54: East | H54: Kolkata | I54: 5 | J54: 1288.11 | K54: 0.15 | L54: 5474.47 | M54: Marketplace | N54: Debit Card | O54: Completed | P54: Sneha
A55: ORD50054 | B55: 46005 | C55: CUST1188 | D55: P015 | E55: Phone Stand | F55: Accessories | G55: West | I55: 5 | J55: 672.38 | K55: 0.2 | L55: 2689.52 | M55: Online | N55: UPI | O55: Completed | P55: Kiran
A56: ORD50055 | B56: 45444 | C56: CUST1149 | D56: P003 | E56: Keyboard | F56: Electronics | G56: North | H56: Lucknow | I56: 3 | J56: 1790.2 | L56: 5370.6 | M56: Store | N56: Net Banking | O56: Cancelled | P56: Vikram
A57: ORD50056 | B57: 46020 | C57: CUST1220 | D57: P008 | E57: Pen Set | F57: Stationery | G57: South | H57: Hyderabad | I57: 2 | J57: 235.18 | K57: 0.1 | L57: 423.32 | M57: Marketplace | N57: UPI | O57: Cancelled | P57: Anil
A58: ORD50057 | B58: 45737 | C58: CUST1202 | D58: P010 | E58: USB-C Hub | F58: Electronics | G58: East | H58: Patna | I58: 3 | J58: 2260.27 | K58: 0.2 | L58: 5424.65 | M58: Store | N58: Net Banking | O58: Returned | P58: Meena
...

Sheet Clean_data 
A1: Order_ID | B1: Order_Date | C1: Customer_ID | D1: Product_ID | E1: Product_Name | F1: Category | G1: Region | H1: City | I1: Quantity | J1: Unit_Price | K1: Discount | L1: Sales_Amount | M1: Sales_Channel | N1: Payment_Method | O1: Order_Status | P1: Salesperson | Q1: Order_Status_Clean | R1: Sales_Channel_Clean | S1: Payment_Method_Clean | T1: Category_Clean | U1: Quantity_Status | V1: Quantity_Review | W1: Discount_Status | X1: Gross_Sales | Y1: Net_Sales
A2: ORD50001 | B2: 45373 | C2: CUST1224 | D2: P012 | E2: Water Bottle | F2: Accessories | G2: East | H2: Kolkata | I2: 3 | J2: 876.84 | K2: 0.08 | L2: 2420.08 | M2: Online | N2: Debit Card | O2: Returned | P2: Arjun | Q2: =PROPER(O2) -> Returned | R2: =PROPER(M2) -> Online | S2: {=PROPER(N2:N1529)} -> Debit Card | T2: {=PROPER(F2:F1529)} -> Accessories | U2: =IF(I2<=0,"INVALID","VALID") -> VALID | V2: =IF(I2>100,"REVIEW","NORMAL") -> NORMAL | W2: =IF(OR(K2<0,K2>1),"Invalid","Valid") -> Valid | X2: =I2*J2 -> 2630.52 | Y2: =I2*J2-(I2*J2*K2) -> 2420.0784
A3: ORD50002 | B3: 45986 | C3: CUST1131 | D3: P011 | E3: Headphones | F3: Electronics | G3: West | H3: Pune | I3: 3 | J3: 3174.6 | K3: 0 | L3: 9523.8 | M3: Online | N3: Cash on Delivery | O3: Cancelled | P3: Arjun | Q3: =PROPER(O3) -> Cancelled | R3: =PROPER(M3) -> Online | S3: Cash On Delivery | T3: Electronics | U3: =IF(I3<=0,"INVALID","VALID") -> VALID | V3: =IF(I3>100,"REVIEW","NORMAL") -> NORMAL | W3: =IF(OR(K3<0,K3>1),"Invalid","Valid") -> Valid | X3: =I3*J3 -> 9523.8 | Y3: =I3*J3-(I3*J3*K3) -> 9523.8
A4: ORD50003 | B4: 45659 | C4: CUST1060 | D4: P013 | E4: Desk Lamp | F4: Furniture | G4: East | H4: Ranchi | I4: 3 | J4: 1613.97 | K4: 0.08 | L4: 4454.56 | M4: Online | N4: Cash on Delivery | O4: Cancelled | P4: Rahul | Q4: =PROPER(O4) -> Cancelled | R4: =PROPER(M4) -> Online | S4: Cash On Delivery | T4: Furniture | U4: =IF(I4<=0,"INVALID","VALID") -> VALID | V4: =IF(I4>100,"REVIEW","NORMAL") -> NORMAL | W4: =IF(OR(K4<0,K4>1),"Invalid","Valid") -> Valid | X4: =I4*J4 -> 4841.91 | Y4: =I4*J4-(I4*J4*K4) -> 4454.5572
A5: ORD50004 | B5: 45868 | C5: CUST1116 | D5: P003 | E5: Keyboard | F5: Electronics | G5: West | H5: Surat | I5: 4 | J5: 1935.56 | K5: 0.05 | L5: 7355.13 | M5: Marketplace | N5: Net Banking | O5: Cancelled | P5: Priya | Q5: =PROPER(O5) -> Cancelled | R5: =PROPER(M5) -> Marketplace | S5: Net Banking | T5: Electronics | U5: =IF(I5<=0,"INVALID","VALID") -> VALID | V5: =IF(I5>100,"REVIEW","NORMAL") -> NORMAL | W5: =IF(OR(K5<0,K5>1),"Invalid","Valid") -> Valid | X5: =I5*J5 -> 7742.24 | Y5: =I5*J5-(I5*J5*K5) -> 7355.128
A6: ORD50005 | B6: 45623 | C6: CUST1041 | D6: P008 | E6: Pen Set | F6: Stationery | G6: South | H6: Chennai | I6: 1 | J6: 226.44 | K6: 0.08 | L6: 208.32 | M6: Marketplace | N6: Credit Card | O6: Returned | P6: Sneha | Q6: =PROPER(O6) -> Returned | R6: =PROPER(M6) -> Marketplace | S6: Credit Card | T6: Stationery | U6: =IF(I6<=0,"INVALID","VALID") -> VALID | V6: =IF(I6>100,"REVIEW","NORMAL") -> NORMAL | W6: =IF(OR(K6<0,K6>1),"Invalid","Valid") -> Valid | X6: =I6*J6 -> 226.44 | Y6: =I6*J6-(I6*J6*K6) -> 208.3248
A7: ORD50006 | B7: 45589 | C7: CUST1121 | D7: P014 | E7: Webcam | F7: Electronics | G7: South | H7: Hyderabad | I7: 1 | J7: 2660.88 | K7: 0.08 | L7: 2448.01 | M7: Marketplace | N7: Debit Card | O7: Completed | P7: Priya | Q7: =PROPER(O7) -> Completed | R7: =PROPER(M7) -> Marketplace | S7: Debit Card | T7: Electronics | U7: =IF(I7<=0,"INVALID","VALID") -> VALID | V7: =IF(I7>100,"REVIEW","NORMAL") -> NORMAL | W7: =IF(OR(K7<0,K7>1),"Invalid","Valid") -> Valid | X7: =I7*J7 -> 2660.88 | Y7: =I7*J7-(I7*J7*K7) -> 2448.0096
A8: ORD50007 | B8: 45806 | C8: CUST1217 | D8: P011 | E8: Headphones | F8: Electronics | G8: West | H8: Mumbai | I8: 3 | J8: 3302.54 | K8: 0.03 | L8: 9610.39 | M8: Online | N8: Net Banking | O8: Cancelled | P8: Sneha | Q8: =PROPER(O8) -> Cancelled | R8: =PROPER(M8) -> Online | S8: Net Banking | T8: Electronics | U8: =IF(I8<=0,"INVALID","VALID") -> VALID | V8: =IF(I8>100,"REVIEW","NORMAL") -> NORMAL | W8: =IF(OR(K8<0,K8>1),"Invalid","Valid") -> Valid | X8: =I8*J8 -> 9907.62 | Y8: =I8*J8-(I8*J8*K8) -> 9610.3914
A9: ORD50008 | B9: 46025 | C9: CUST1166 | D9: P013 | E9: Desk Lamp | F9: Furniture | G9: South | H9: Hyderabad | I9: 5 | J9: 1646.72 | K9: 0.05 | L9: 7821.92 | M9: Marketplace | N9: UPI | O9: Cancelled | P9: Anil | Q9: =PROPER(O9) -> Cancelled | R9: =PROPER(M9) -> Marketplace | S9: Upi | T9: Furniture | U9: =IF(I9<=0,"INVALID","VALID") -> VALID | V9: =IF(I9>100,"REVIEW","NORMAL") -> NORMAL | W9: =IF(OR(K9<0,K9>1),"Invalid","Valid") -> Valid | X9: =I9*J9 -> 8233.6 | Y9: =I9*J9-(I9*J9*K9) -> 7821.92
A10: ORD50009 | B10: 46018 | C10: CUST1184 | D10: P012 | E10: Water Bottle | F10: Accessories | G10: West | H10: Ahmedabad | I10: 4 | J10: 888.18 | K10: 0.08 | L10: 3268.5 | M10: Store | N10: Debit Card | O10: Completed | P10: Anil | Q10: =PROPER(O10) -> Completed | R10: =PROPER(M10) -> Store | S10: Debit Card | T10: Accessories | U10: =IF(I10<=0,"INVALID","VALID") -> VALID | V10: =IF(I10>100,"REVIEW","NORMAL") -> NORMAL | W10: =IF(OR(K10<0,K10>1),"Invalid","Valid") -> Valid | X10: =I10*J10 -> 3552.72 | Y10: =I10*J10-(I10*J10*K10) -> 3268.5024
A11: ORD50010 | B11: 45419 | C11: CUST1223 | D11: P004 | E11: Monitor 24-inch | F11: Electronics | G11: North | H11: Lucknow | I11: 3 | J11: 12442.19 | K11: 0.1 | L11: 33593.91 | M11: Online | N11: Net Banking | O11: Completed | P11: Arjun | Q11: =PROPER(O11) -> Completed | R11: =PROPER(M11) -> Online | S11: Net Banking | T11: Electronics | U11: =IF(I11<=0,"INVALID","VALID") -> VALID | V11: =IF(I11>100,"REVIEW","NORMAL") -> NORMAL | W11: =IF(OR(K11<0,K11>1),"Invalid","Valid") -> Valid | X11: =I11*J11 -> 37326.57 | Y11: =I11*J11-(I11*J11*K11) -> 33593.913
A12: ORD50011 | B12: 45807 | C12: CUST1080 | D12: P009 | E12: Backpack | F12: Accessories | G12: North | H12: Jaipur | I12: 3 | J12: 1664.88 | K12: 0.15 | L12: 4245.44 | M12: Store | N12: Cash on Delivery | O12: Completed | P12: Rahul | Q12: =PROPER(O12) -> Completed | R12: =PROPER(M12) -> Store | S12: Cash On Delivery | T12: Accessories | U12: =IF(I12<=0,"INVALID","VALID") -> VALID | V12: =IF(I12>100,"REVIEW","NORMAL") -> NORMAL | W12: =IF(OR(K12<0,K12>1),"Invalid","Valid") -> Valid | X12: =I12*J12 -> 4994.64 | Y12: =I12*J12-(I12*J12*K12) -> 4245.444
A13: ORD50012 | B13: 45664 | C13: CUST1223 | D13: P015 | E13: Phone Stand | F13: Accessories | G13: West | H13: Pune | I13: 1 | J13: 650.53 | K13: 0.03 | L13: 631.01 | M13: Marketplace | N13: Credit Card | O13: Completed | P13: Arjun | Q13: =PROPER(O13) -> Completed | R13: =PROPER(M13) -> Marketplace | S13: Credit Card | T13: Accessories | U13: =IF(I13<=0,"INVALID","VALID") -> VALID | V13: =IF(I13>100,"REVIEW","NORMAL") -> NORMAL | W13: =IF(OR(K13<0,K13>1),"Invalid","Valid") -> Valid | X13: =I13*J13 -> 650.53 | Y13: =I13*J13-(I13*J13*K13) -> 631.0141
A14: ORD50013 | B14: 45407 | C14: CUST1173 | D14: P009 | E14: Backpack | F14: Accessories | G14: East | H14: Bhubaneswar | I14: 4 | J14: 1773.04 | K14: 0.2 | L14: 5673.73 | M14: Marketplace | N14: Credit Card | O14: Completed | P14: Rahul | Q14: =PROPER(O14) -> Completed | R14: =PROPER(M14) -> Marketplace | S14: Credit Card | T14: Accessories | U14: =IF(I14<=0,"INVALID","VALID") -> VALID | V14: =IF(I14>100,"REVIEW","NORMAL") -> NORMAL | W14: =IF(OR(K14<0,K14>1),"Invalid","Valid") -> Valid | X14: =I14*J14 -> 7092.16 | Y14: =I14*J14-(I14*J14*K14) -> 5673.728
... A31: ORD50030 | B31: 45973 | C31: CUST1009 | D31: P006 | E31: Desk | F31: Furniture | G31: South | H31: Hyderabad | I31: 1 | J31: 6901.6 | K31: 0.2 | L31: 5521.28 | M31: Online | N31: Cash on Delivery | O31: Returned | P31: Priya | Q31: =PROPER(O31) -> Returned | R31: =PROPER(M31) -> Online | S31: Cash On Delivery | T31: Furniture | U31: =IF(I31<=0,"INVALID","VALID") -> VALID | V31: =IF(I31>100,"REVIEW","NORMAL") -> NORMAL | W31: =IF(OR(K31<0,K31>1),"Invalid","Valid") -> Valid | X31: =I31*J31 -> 6901.6 | Y31: =I31*J31-(I31*J31*K31) -> 5521.28
A32: ORD50031 | B32: 45973 | D32: P003 | E32: Keyboard | F32: Electronics | G32: South | H32: Visakhapatnam | I32: 3 | J32: 1712.57 | K32: 0.15 | L32: 4367.05 | M32: Online | N32: Cash on Delivery | O32: Cancelled | P32: Rahul | Q32: =PROPER(O32) -> Cancelled | R32: =PROPER(M32) -> Online | S32: Cash On Delivery | T32: Electronics | U32: =IF(I32<=0,"INVALID","VALID") -> VALID | V32: =IF(I32>100,"REVIEW","NORMAL") -> NORMAL | W32: =IF(OR(K32<0,K32>1),"Invalid","Valid") -> Valid | X32: =I32*J32 -> 5137.71 | Y32: =I32*J32-(I32*J32*K32) -> 4367.0535
A33: ORD50032 | B33: 46178 | D33: P008 | E33: Pen Set | F33: Stationery | G33: East | H33: Kolkata | I33: 3 | J33: 202.89 | K33: 0.03 | L33: 590.41 | M33: Online | N33: UPI | O33: Completed | P33: Arjun | Q33: =PROPER(O33) -> Completed | R33: =PROPER(M33) -> Online | S33: Upi | T33: Stationery | U33: =IF(I33<=0,"INVALID","VALID") -> VALID | V33: =IF(I33>100,"REVIEW","NORMAL") -> NORMAL | W33: =IF(OR(K33<0,K33>1),"Invalid","Valid") -> Valid | X33: =I33*J33 -> 608.67 | Y33: =I33*J33-(I33*J33*K33) -> 590.4099
A34: ORD50033 | B34: 46176 | C34: CUST1181 | D34: P002 | E34: Wireless Mouse | F34: Electronics | G34: South | H34: Visakhapatnam | I34: 0 | J34: 1215.57 | K34: 0.2 | L34: 2917.37 | M34: Online | N34: Cash on Delivery | O34: Cancelled | P34: Anil | Q34: =PROPER(O34) -> Cancelled | R34: =PROPER(M34) -> Online | S34: Cash On Delivery | T34: Electronics | U34: =IF(I34<=0,"INVALID","VALID") -> INVALID | V34: =IF(I34>100,"REVIEW","NORMAL") -> NORMAL | W34: =IF(OR(K34<0,K34>1),"Invalid","Valid") -> Valid | X34: =I34*J34 -> 0 | Y34: =I34*J34-(I34*J34*K34) -> 0
A35: ORD50034 | B35: 45944 | C35: CUST1148 | D35: P002 | E35: Wireless Mouse | F35: Electronics | G35: East | H35: Ranchi | I35: 5 | J35: 1127.76 | K35: 0 | L35: 5638.8 | M35: Online | N35: Credit Card | O35: Returned | P35: Rahul | Q35: =PROPER(O35) -> Returned | R35: =PROPER(M35) -> Online | S35: Credit Card | T35: Electronics | U35: =IF(I35<=0,"INVALID","VALID") -> VALID | V35: =IF(I35>100,"REVIEW","NORMAL") -> NORMAL | W35: =IF(OR(K35<0,K35>1),"Invalid","Valid") -> Valid | X35: =I35*J35 -> 5638.8 | Y35: =I35*J35-(I35*J35*K35) -> 5638.8
A36: ORD50035 | B36: 45412 | C36: CUST1249 | D36: P008 | E36: Pen Set | F36: Stationery | G36: East | H36: Ranchi | I36: 4 | J36: 212.48 | K36: 0.05 | L36: 807.42 | M36: Marketplace | N36: Debit Card | O36: Completed | P36: Kiran | Q36: =PROPER(O36) -> Completed | R36: =PROPER(M36) -> Marketplace | S36: Debit Card | T36: Stationery | U36: =IF(I36<=0,"INVALID","VALID") -> VALID | V36: =IF(I36>100,"REVIEW","NORMAL") -> NORMAL | W36: =IF(OR(K36<0,K36>1),"Invalid","Valid") -> Valid | X36: =I36*J36 -> 849.92 | Y36: =I36*J36-(I36*J36*K36) -> 807.424
A37: ORD50036 | B37: 45798 | C37: CUST1195 | D37: P003 | E37: Keyboard | F37: Electronics | G37: East | H37: Bhubaneswar | I37: 5 | J37: 1696.42 | K37: 0 | L37: 8482.1 | M37: Online | N37: Cash on Delivery | O37: Completed | P37: Kiran | Q37: =PROPER(O37) -> Completed | R37: =PROPER(M37) -> Online | S37: Cash On Delivery | T37: Electronics | U37: =IF(I37<=0,"INVALID","VALID") -> VALID | V37: =IF(I37>100,"REVIEW","NORMAL") -> NORMAL | W37: =IF(OR(K37<0,K37>1),"Invalid","Valid") -> Valid | X37: =I37*J37 -> 8482.1 | Y37: =I37*J37-(I37*J37*K37) -> 8482.1
A38: ORD50037 | B38: 45457 | C38: CUST1122 | D38: P014 | E38: Webcam | F38: Electronics | G38: East | H38: Ranchi | I38: 5 | J38: 2927.57 | K38: 0.08 | L38: 13466.82 | M38: Online | N38: Net Banking | O38: Completed | P38: Rahul | Q38: =PROPER(O38) -> Completed | R38: =PROPER(M38) -> Online | S38: Net Banking | T38: Electronics | U38: =IF(I38<=0,"INVALID","VALID") -> VALID | V38: =IF(I38>100,"REVIEW","NORMAL") -> NORMAL | W38: =IF(OR(K38<0,K38>1),"Invalid","Valid") -> Valid | X38: =I38*J38 -> 14637.85 | Y38: =I38*J38-(I38*J38*K38) -> 13466.822
A39: ORD50038 | B39: 46048 | C39: CUST1199 | D39: P004 | E39: Monitor 24-inch | F39: Electronics | G39: West | H39: Ahmedabad | I39: 3 | J39: 12561.54 | K39: 0.03 | L39: 36554.08 | M39: Marketplace | N39: Cash on Delivery | O39: Cancelled | P39: Kiran | Q39: =PROPER(O39) -> Cancelled | R39: =PROPER(M39) -> Marketplace | S39: Cash On Delivery | T39: Electronics | U39: =IF(I39<=0,"INVALID","VALID") -> VALID | V39: =IF(I39>100,"REVIEW","NORMAL") -> NORMAL | W39: =IF(OR(K39<0,K39>1),"Invalid","Valid") -> Valid | X39: =I39*J39 -> 37684.62 | Y39: =I39*J39-(I39*J39*K39) -> 36554.081
A40: ORD50039 | B40: 45556 | C40: CUST1111 | D40: P007 | E40: Notebook Pack | F40: Stationery | G40: North | H40: Chandigarh | I40: 2 | J40: 460.94 | K40: 0.2 | L40: 737.5 | M40: Marketplace | N40: Credit Card | O40: Completed | P40: Kiran | Q40: =PROPER(O40) -> Completed | R40: =PROPER(M40) -> Marketplace | S40: Credit Card | T40: Stationery | U40: =IF(I40<=0,"INVALID","VALID") -> VALID | V40: =IF(I40>100,"REVIEW","NORMAL") -> NORMAL | W40: =IF(OR(K40<0,K40>1),"Invalid","Valid") -> Valid | X40: =I40*J40 -> 921.88 | Y40: =I40*J40-(I40*J40*K40) -> 737.504
A41: ORD50040 | B41: 45518 | C41: CUST1250 | D41: P005 | E41: Office Chair | F41: Furniture | G41: North | H41: Delhi | I41: 5 | J41: 9981.18 | K41: 0.15 | L41: 42420.01 | M41: Marketplace | N41: UPI | O41: Completed | P41: Kiran | Q41: =PROPER(O41) -> Completed | R41: =PROPER(M41) -> Marketplace | S41: Upi | T41: Furniture | U41: =IF(I41<=0,"INVALID","VALID") -> VALID | V41: =IF(I41>100,"REVIEW","NORMAL") -> NORMAL | W41: =IF(OR(K41<0,K41>1),"Invalid","Valid") -> Valid | X41: =I41*J41 -> 49905.9 | Y41: =I41*J41-(I41*J41*K41) -> 42420.015
A42: ORD50041 | B42: 45618 | C42: CUST1081 | D42: P003 | E42: Keyboard | F42: Electronics | G42: North | H42: Chandigarh | I42: 5 | J42: 1697.44 | K42: 0.05 | L42: 8062.84 | M42: Marketplace | N42: Debit Card | O42: Completed | P42: Priya | Q42: =PROPER(O42) -> Completed | R42: =PROPER(M42) -> Marketplace | S42: Debit Card | T42: Electronics | U42: =IF(I42<=0,"INVALID","VALID") -> VALID | V42: =IF(I42>100,"REVIEW","NORMAL") -> NORMAL | W42: =IF(OR(K42<0,K42>1),"Invalid","Valid") -> Valid | X42: =I42*J42 -> 8487.2 | Y42: =I42*J42-(I42*J42*K42) -> 8062.84
A43: ORD50042 | B43: 45551 | C43: CUST1185 | D43: P009 | E43: Backpack | F43: Accessories | G43: North | H43: Delhi | I43: 3 | J43: 1662.09 | K43: 0 | L43: 4986.27 | M43: Online | N43: UPI | O43: Cancelled | P43: Anil | Q43: =PROPER(O43) -> Cancelled | R43: =PROPER(M43) -> Online | S43: Upi | T43: Accessories | U43: =IF(I43<=0,"INVALID","VALID") -> VALID | V43: =IF(I43>100,"REVIEW","NORMAL") -> NORMAL | W43: =IF(OR(K43<0,K43>1),"Invalid","Valid") -> Valid | X43: =I43*J43 -> 4986.27 | Y43: =I43*J43-(I43*J43*K43) -> 4986.27
A44: ORD50043 | B44: 45683 | C44: CUST1103 | D44: P009 | E44: Backpack | F44: Accessories | G44: East | H44: Ranchi | I44: 4 | J44: 1747.58 | K44: 0.15 | L44: 5941.77 | M44: Store | N44: Net Banking | O44: Returned | P44: Meena | Q44: =PROPER(O44) -> Returned | R44: =PROPER(M44) -> Store | S44: Net Banking | T44: Accessories | U44: =IF(I44<=0,"INVALID","VALID") -> VALID | V44: =IF(I44>100,"REVIEW","NORMAL") -> NORMAL | W44: =IF(OR(K44<0,K44>1),"Invalid","Valid") -> Valid | X44: =I44*J44 -> 6990.32 | Y44: =I44*J44-(I44*J44*K44) -> 5941.772
A45: ORD50044 | B45: 46068 | C45: CUST1060 | D45: P009 | E45: Backpack | F45: Accessories | G45: North | H45: Delhi | I45: 3 | J45: 1724.18 | K45: 0.03 | L45: 5017.36 | M45: Store | N45: Debit Card | O45: Returned | P45: Sneha | Q45: =PROPER(O45) -> Returned | R45: =PROPER(M45) -> Store | S45: Debit Card | T45: Accessories | U45: =IF(I45<=0,"INVALID","VALID") -> VALID | V45: =IF(I45>100,"REVIEW","NORMAL") -> NORMAL | W45: =IF(OR(K45<0,K45>1),"Invalid","Valid") -> Valid | X45: =I45*J45 -> 5172.54 | Y45: =I45*J45-(I45*J45*K45) -> 5017.3638
... A54: ORD50053 | B54: 45821 | C54: CUST1036 | D54: P002 | E54: Wireless Mouse | F54: Electronics | G54: East | H54: Kolkata | I54: 5 | J54: 1288.11 | K54: 0.15 | L54: 5474.47 | M54: Marketplace | N54: Debit Card | O54: Completed | P54: Sneha | Q54: =PROPER(O54) -> Completed | R54: =PROPER(M54) -> Marketplace | S54: Debit Card | T54: Electronics | U54: =IF(I54<=0,"INVALID","VALID") -> VALID | V54: =IF(I54>100,"REVIEW","NORMAL") -> NORMAL | W54: =IF(OR(K54<0,K54>1),"Invalid","Valid") -> Valid | X54: =I54*J54 -> 6440.55 | Y54: =I54*J54-(I54*J54*K54) -> 5474.4675
A55: ORD50054 | B55: 46005 | C55: CUST1188 | D55: P015 | E55: Phone Stand | F55: Accessories | G55: West | I55: 5 | J55: 672.38 | K55: 0.2 | L55: 2689.52 | M55: Online | N55: UPI | O55: Completed | P55: Kiran | Q55: =PROPER(O55) -> Completed | R55: =PROPER(M55) -> Online | S55: Upi | T55: Accessories | U55: =IF(I55<=0,"INVALID","VALID") -> VALID | V55: =IF(I55>100,"REVIEW","NORMAL") -> NORMAL | W55: =IF(OR(K55<0,K55>1),"Invalid","Valid") -> Valid | X55: =I55*J55 -> 3361.9 | Y55: =I55*J55-(I55*J55*K55) -> 2689.52
A56: ORD50055 | B56: 45444 | C56: CUST1149 | D56: P003 | E56: Keyboard | F56: Electronics | G56: North | H56: Lucknow | I56: 3 | J56: 1790.2 | L56: 5370.6 | M56: Store | N56: Net Banking | O56: Cancelled | P56: Vikram | Q56: =PROPER(O56) -> Cancelled | R56: =PROPER(M56) -> Store | S56: Net Banking | T56: Electronics | U56: =IF(I56<=0,"INVALID","VALID") -> VALID | V56: =IF(I56>100,"REVIEW","NORMAL") -> NORMAL | W56: =IF(OR(K56<0,K56>1),"Invalid","Valid") -> Valid | X56: =I56*J56 -> 5370.6 | Y56: =I56*J56-(I56*J56*K56) -> 5370.6
A57: ORD50056 | B57: 46020 | C57: CUST1220 | D57: P008 | E57: Pen Set | F57: Stationery | G57: South | H57: Hyderabad | I57: 2 | J57: 235.18 | K57: 0.1 | L57: 423.32 | M57: Marketplace | N57: UPI | O57: Cancelled | P57: Anil | Q57: =PROPER(O57) -> Cancelled | R57: =PROPER(M57) -> Marketplace | S57: Upi | T57: Stationery | U57: =IF(I57<=0,"INVALID","VALID") -> VALID | V57: =IF(I57>100,"REVIEW","NORMAL") -> NORMAL | W57: =IF(OR(K57<0,K57>1),"Invalid","Valid") -> Valid | X57: =I57*J57 -> 470.36 | Y57: =I57*J57-(I57*J57*K57) -> 423.324
A58: ORD50057 | B58: 45737 | C58: CUST1202 | D58: P010 | E58: USB-C Hub | F58: Electronics | G58: East | H58: Patna | I58: 3 | J58: 2260.27 | K58: 0.2 | L58: 5424.65 | M58: Store | N58: Net Banking | O58: Returned | P58: Meena | Q58: =PROPER(O58) -> Returned | R58: =PROPER(M58) -> Store | S58: Net Banking | T58: Electronics | U58: =IF(I58<=0,"INVALID","VALID") -> VALID | V58: =IF(I58>100,"REVIEW","NORMAL") -> NORMAL | W58: =IF(OR(K58<0,K58>1),"Invalid","Valid") -> Valid | X58: =I58*J58 -> 6780.81 | Y58: =I58*J58-(I58*J58*K58) -> 5424.648
A59: ORD50058 | B59: 45987 | D59: P010 | E59: USB-C Hub | F59: Electronics | G59: South | H59: Hyderabad | I59: 4 | J59: 2134.68 | K59: 0.05 | L59: 8111.78 | M59: Marketplace | O59: Completed | P59: Vikram | Q59: =PROPER(O59) -> Completed | R59: =PROPER(M59) -> Marketplace | T59: Electronics | U59: =IF(I59<=0,"INVALID","VALID") -> VALID | V59: =IF(I59>100,"REVIEW","NORMAL") -> NORMAL | W59: =IF(OR(K59<0,K59>1),"Invalid","Valid") -> Valid | X59: =I59*J59 -> 8538.72 | Y59: =I59*J59-(I59*J59*K59) -> 8111.784
A60: ORD50059 | B60: 45798 | C60: CUST1190 | D60: P007 | E60: Notebook Pack | F60: Stationery | G60: East | H60: Ranchi | I60: 2 | J60: 453.82 | K60: 0 | L60: 907.64 | M60: Marketplace | N60: Credit Card | O60: Cancelled | P60: Kiran | Q60: =PROPER(O60) -> Cancelled | R60: =PROPER(M60) -> Marketplace | S60: Credit Card | T60: Stationery | U60: =IF(I60<=0,"INVALID","VALID") -> VALID | V60: =IF(I60>100,"REVIEW","NORMAL") -> NORMAL | W60: =IF(OR(K60<0,K60>1),"Invalid","Valid") -> Valid | X60: =I60*J60 -> 907.64 | Y60: =I60*J60-(I60*J60*K60) -> 907.64
A61: ORD50060 | B61: 45729 | C61: CUST1221 | D61: P003 | E61: Keyboard | F61: Electronics | G61: South | H61: Chennai | I61: -2 | J61: 1862.71 | K61: 0.2 | L61: 5960.67 | M61: Store | N61: UPI | O61: Completed | P61: Meena | Q61: =PROPER(O61) -> Completed | R61: =PROPER(M61) -> Store | S61: Upi | T61: Electronics | U61: =IF(I61<=0,"INVALID","VALID") -> INVALID | V61: =IF(I61>100,"REVIEW","NORMAL") -> NORMAL | W61: =IF(OR(K61<0,K61>1),"Invalid","Valid") -> Valid | X61: =I61*J61 -> -3725.42 | Y61: =I61*J61-(I61*J61*K61) -> -2980.336
A62: ORD50061 | B62: 46092 | C62: CUST1153 | D62: P010 | E62: USB-C Hub | F62: Electronics | G62: North | H62: Lucknow | I62: 1 | J62: 2265.51 | K62: 0.08 | L62: 2084.27 | M62: Online | N62: UPI | O62: Completed | P62: Arjun | Q62: =PROPER(O62) -> Completed | R62: =PROPER(M62) -> Online | S62: Upi | T62: Electronics | U62: =IF(I62<=0,"INVALID","VALID") -> VALID | V62: =IF(I62>100,"REVIEW","NORMAL") -> NORMAL | W62: =IF(OR(K62<0,K62>1),"Invalid","Valid") -> Valid | X62: =I62*J62 -> 2265.51 | Y62: =I62*J62-(I62*J62*K62) -> 2084.2692
A63: ORD50062 | B63: 46044 | C63: CUST1004 | D63: P007 | E63: Notebook Pack | F63: Stationery | G63: South | H63: Visakhapatnam | I63: 5 | J63: 445.85 | K63: 0.08 | L63: 2050.91 | M63: Store | N63: Cash on Delivery | O63: Cancelled | P63: Meena | Q63: =PROPER(O63) -> Cancelled | R63: =PROPER(M63) -> Store | S63: Cash On Delivery | T63: Stationery | U63: =IF(I63<=0,"INVALID","VALID") -> VALID | V63: =IF(I63>100,"REVIEW","NORMAL") -> NORMAL | W63: =IF(OR(K63<0,K63>1),"Invalid","Valid") -> Valid | X63: =I63*J63 -> 2229.25 | Y63: =I63*J63-(I63*J63*K63) -> 2050.91
A64: ORD50063 | B64: 45788 | C64: CUST1229 | D64: P002 | E64: Wireless Mouse | F64: Electronics | G64: South | H64: Chennai | I64: 5 | J64: 1158.51 | K64: 0 | L64: 5792.55 | M64: Marketplace | N64: UPI | O64: Completed | P64: Arjun | Q64: =PROPER(O64) -> Completed | R64: =PROPER(M64) -> Marketplace | S64: Upi | T64: Electronics | U64: =IF(I64<=0,"INVALID","VALID") -> VALID | V64: =IF(I64>100,"REVIEW","NORMAL") -> NORMAL | W64: =IF(OR(K64<0,K64>1),"Invalid","Valid") -> Valid | X64: =I64*J64 -> 5792.55 | Y64: =I64*J64-(I64*J64*K64) -> 5792.55
...

Sheet Analysis
A1: Question | B1: Answer | D1: Row Labels | E1: Sum of Sales_Amount | G1: Row Labels | H1: Sum of Sales_Amount | J1: Row Labels | K1: Sum of Sales_Amount | M1: Row Labels | N1: Sum of Sales_Amount
A2: Total Sales | B2: =SUM('Clean_data '!L:L) -> 29592577 | D2: Accessories | E2: 938550.64 | G2: Ahmedabad | H2: 2196364.3 | J2: Backpack | K2: 493555.52 | M2: Anil | N2: 4769147.2
A3: Total Quantity | B3: =SUM('Clean_data '!I:I) -> 4592 | D3: Electronics | E3: 23145611 | G3: Bengaluru | H3: 2331377.7 | J3: Desk | K3: 2220172 | M3: Arjun | N3: 4459204.6
A4: Average Sales Amount | B4: =AVERAGE('Clean_data '!L:L) -> 19675.916 | D4: Furniture | E4: 5328687.6 | G4: Bhubaneswar | H4: 2131850.7 | J4: Desk Lamp | K4: 365243.49 | M4: Kiran | N4: 3401028.4
A5: Highest Sales Amount | B5: =MAX('Clean_data '!L:L) -> 339764.2 | D5: Stationery | E5: 179728.6 | G5: Chandigarh | H5: 1769005 | J5: Headphones | K5: 842475.75 | M5: Meena | N5: 2754345.2
A6: Lowest Sales Amount | B6: =MIN('Clean_data '!L:L) -> 166.5 | D6: Grand Total | E6: 29592577 | G6: Chennai | H6: 1300171.9 | J6: Keyboard | K6: 573377.51 | M6: Priya | N6: 3727292.8
A7: Completed Orders | B7: =COUNTIF('Clean_data '!O:O,"completed") -> 1026 | G7: Delhi | H7: 1193556.8 | J7: Laptop 15-inch | K7: 16702445 | M7: Rahul | N7: 2861025.3
A8: Cancelled Orders | B8: =COUNTIF('Clean_data '!O:O,"cancelled") -> 243 | G8: Hyderabad | H8: 1483606.3 | J8: Monitor 24-inch | K8: 3581792.5 | M8: Sneha | N8: 3237769.7
A9: Returned Orders | B9: =COUNTIF('Clean_data '!O:O,"returned") -> 235 | D9: Row Labels | E9: Sum of Sales_Amount | G9: Jaipur | H9: 1823153.4 | J9: Notebook Pack | K9: 117802.69 | M9: Vikram | N9: 3963068.4
D10: East | E10: 8134892.6 | G10: Kolkata | H10: 2453114.7 | J10: Office Chair | K10: 2743272.1 | M10: Grand Total | N10: 29172882
D11: North | E11: 7064448.8 | G11: Lucknow | H11: 2222621.3 | J11: Pen Set | K11: 61925.91
A12: Row Labels | B12: Sum of Sales_Amount | D12: South | E12: 7093523.5 | G12: Mumbai | H12: 1334417.7 | J12: Phone Stand | K12: 182259.21
A13: Backpack | B13: 493555.52 | D13: West | E13: 7299712.6 | G13: Patna | H13: 1591722.9 | J13: USB-C Hub | K13: 530135.43 | M13: Row Labels | N13: Sum of Sales_Amount
A14: Desk | B14: 2220172 | D14: Grand Total | E14: 29592577 | G14: Pune | H14: 2165126.5 | J14: Water Bottle | K14: 262735.91 | M14: Marketplace | N14: 9144489.5
A15: Desk Lamp | B15: 365243.49 | G15: Ranchi | H15: 1937343.7 | J15: Webcam | K15: 594958.93 | M15: Online | N15: 11563653
A16: Headphones | B16: 842475.75 | G16: Surat | H16: 1550596.6 | J16: Wireless Mouse | K16: 320425.15 | M16: Store | N16: 8884435.1
A17: Keyboard | B17: 573377.51 | G17: Visakhapatnam | H17: 1933071.1 | J17: Grand Total | K17: 29592577 | M17: Grand Total | N17: 29592577
A18: Laptop 15-inch | B18: 16702445 | G18: Grand Total | H18: 29417100
A19: Monitor 24-inch | B19: 3581792.5
A20: Office Chair | B20: 2743272.1
A21: USB-C Hub | B21: 530135.43
A22: Webcam | B22: 594958.93
A23: Grand Total | B23: 28647429
